2025-02-14 10:23:25,179 - INFO - [Train] Using device: cuda
2025-02-14 10:23:31,200 - INFO - Loaded model checkpoint from /mnt/c/Users/didri/Desktop/Programmering/ArtificalintelligenceModels/UNet-Model_Vocal_Isolation/Unet_model_Audio_Seperation/Model_Weights/CheckPoints/Training/checkpoint_epoch_9
2025-02-14 10:23:31,378 - INFO - [Train] Epoch 1/1 started.

2025-02-14 10:24:10,290 - ERROR - [Train] Error during training: Caught UnboundLocalError in DataLoader worker process 0.
Original Traceback (most recent call last):
  File "/home/didrik/.venvs/global_env/lib/python3.12/site-packages/torch/utils/data/_utils/worker.py", line 349, in _worker_loop
    data = fetcher.fetch(index)  # type: ignore[possibly-undefined]
           ^^^^^^^^^^^^^^^^^^^^
  File "/home/didrik/.venvs/global_env/lib/python3.12/site-packages/torch/utils/data/_utils/fetch.py", line 55, in fetch
    return self.collate_fn(data)
           ^^^^^^^^^^^^^^^^^^^^^
  File "/mnt/c/Users/didri/Desktop/Programmering/ArtificalintelligenceModels/UNet-Model_Vocal_Isolation/Unet_model_Audio_Seperation/Training/Externals/Dataloader.py", line 64, in robust_collate_fn
    if BatchCount <= 2:
       ^^^^^^^^^^
UnboundLocalError: cannot access local variable 'BatchCount' where it is not associated with a value

